<?xml version="1.0" ?>
<robot name="vadrouilleur" xmlns:xacro="http://ros.org/wiki/xacro">
  <xacro:include filename="$(find vadrouilleur_description)/urdf/common_properties.xacro"/>
  <xacro:include filename="$(find vadrouilleur_description)/urdf/vadrouilleur_gazebo.gazebo.xacro"/>

  <link name="base_footprint"/>

  <joint name="base_joint" type="fixed">
    <parent link="base_link"/>
    <child link="base_footprint"/>
    <origin xyz="0 0 0.1" rpy="0 0 0"/>
  </joint>

  <link name="base_link">
    <visual>
      <origin xyz="0 0 0" rpy="0 0 0"/>
      <geometry>
        <cylinder length="0.1" radius="0.2"/>
      </geometry>
    </visual>

    <collision>
      <origin xyz="0 0 0" rpy="0 0 0"/>
      <geometry>
        <cylinder length="0.1" radius="0.2"/>
      </geometry>
    </collision>

    <inertial>
      <origin xyz="0 0 0" />
      <mass value="0.5" />
      <inertia ixx="0.04083333333333334" ixy="0.0" ixz="0.0"
              iyy="0.04083333333333334" iyz="0.0"
              izz="0.08000000000000002" />
    </inertial>
  </link>


  <joint name="wheel_left_joint" type="continuous">
    <parent link="base_link"/>
    <child link="wheel_left_link"/>
    <origin xyz="-0.1 0.26 -0.04" rpy="-1.57 0 0"/>
    <axis xyz="0 0 1"/>
  </joint>

  <link name="wheel_left_link">
    <visual>
      <origin xyz="0 0 0" rpy="0 0 0"/>
      <geometry>
        <cylinder length="0.04" radius="0.06"/>
      </geometry>
      <material name="dark"/>
    </visual>

    <collision>
      <origin xyz="0 0 0" rpy="0 0 0"/>
      <geometry>
        <cylinder length="0.04" radius="0.06"/>
      </geometry>
    </collision>

    <inertial>
      <origin xyz="0 0 0" />
      <mass value="0.1" />
      <inertia ixx="0.0010333333333333334" ixy="0.0" ixz="0.0"
              iyy="0.0010333333333333334" iyz="0.0"
              izz="0.0018" />
    </inertial>
  </link>

  <joint name="wheel_right_joint" type="continuous">
    <parent link="base_link"/>
    <child link="wheel_right_link"/>
    <origin xyz="-0.1 -0.26 -0.04" rpy="-1.57 0 0"/>
    <axis xyz="0 0 1"/>
  </joint>

  <link name="wheel_right_link">
    <visual>
      <origin xyz="0 0 0" rpy="0 0 0"/>
      <geometry>
        <cylinder length="0.04" radius="0.06"/>
      </geometry>
      <material name="dark"/>
    </visual>

    <collision>
      <origin xyz="0 0 0" rpy="0 0 0"/>
      <geometry>
        <cylinder length="0.04" radius="0.06"/>
      </geometry>
    </collision>

    <inertial>
      <origin xyz="0 0 0" />
      <mass value="0.1" />
      <inertia ixx="0.0010333333333333334" ixy="0.0" ixz="0.0"
              iyy="0.0010333333333333334" iyz="0.0"
              izz="0.0018" />
    </inertial>
  </link>  

  <joint name="caster_back_joint" type="fixed">
    <parent link="base_link"/>
    <child link="caster_back_link"/>
    <origin xyz="0.1 0 -0.05" rpy="-1.57 0 0"/>
  </joint>
  
  <link name="caster_back_link">
    <visual>
      <origin xyz="0 0 0" rpy="0 0 0"/>
      <geometry>
	      <sphere radius="0.05"/>
      </geometry>
      <material name="dark"/>
    </visual>  

    <collision>
      <origin xyz="0 0 0" rpy="0 0 0"/>
      <geometry>
        <sphere radius="0.05"/>
      </geometry>
    </collision>

    <inertial>
      <origin xyz="0 0 0" />
      <mass value="0.05" />
      <inertia ixx="5.0000000000000016e-05" ixy="0.0" ixz="0.0"
              iyy="5.0000000000000016e-05" iyz="0.0"
              izz="5.0000000000000016e-05" />
    </inertial>
  </link>

  <joint name="essieu_joint" type="fixed">
    <parent link="base_link"/>
    <child link="essieu" />
    <origin xyz="-0.1 0 -0.04" rpy="1.57 0 0"/>
  </joint>

  <link name="essieu">
    <visual>
      <origin xyz="0 0 0" rpy="0 0 0"/>
      <geometry>
        <cylinder length="0.46" radius="0.01"/>
      </geometry>
      <material name="dark"/>
    </visual>

    <collision>
      <origin xyz="0 0 0" rpy="0 0 0"/>
      <geometry>
        <cylinder length="0.46" radius="0.01"/>
      </geometry>
    </collision>

    <inertial>
      <origin xyz="0 0 0" />
      <mass value="0.2" />
      <inertia ixx="0.04823333333333333" ixy="0.0" ixz="0.0"
              iyy="0.04823333333333333" iyz="0.0"
              izz="0.0002" />
    </inertial>
  </link>

  <joint name="imu_joint" type="fixed">
    <parent link="base_link"/>
    <child link="imu_link"/>
    <origin xyz="-0.032 0 0.068" rpy="0 0 0"/>
  </joint>

  <link name="imu_link"/>


  <joint name="lidar_joint" type="fixed">
    <parent link="base_link"/>
    <child link="lidar_link"/>
    <origin xyz="-0.1 0 0.1" rpy="0 0 0"/>
  </joint>

  <link name="lidar_link">
    <visual>
      <origin xyz="0 0 0" rpy="0 0 0"/>
      <geometry>
        <cylinder length="0.1" radius="0.08"/>
      </geometry>
    </visual>

    <collision>
      <origin xyz="0 0 0" rpy="0 0 0"/>
      <geometry>
        <cylinder length="0.1" radius="0.08"/>
      </geometry>
    </collision>

    <inertial>
      <origin xyz="0 0 0" />
      <mass value="0.05" />
      <inertia ixx="0.16083333333333336" ixy="0.0" ixz="0.0"
              iyy="0.16083333333333336" iyz="0.0"
              izz="0.32000000000000006" />
    </inertial>
  </link>

  <link name="camera_link">
  <visual>
    <origin xyz="0 0 0" rpy="0 0 0"/>
    <geometry>
      <box size="0.015 0.130 0.022"/>
    </geometry>
  </visual>

  <collision>
    <origin xyz="0 0 0" rpy="0 0 0"/>
    <geometry>
      <box size="0.015 0.130 0.022"/>
    </geometry>
  </collision>

  <inertial>
    <origin xyz="0 0 0" rpy="0 0 0"/>
    <mass value="0.035"/>
    <inertia ixx="0.001"  ixy="0"  ixz="0" iyy="0.001" iyz="0" izz="0.001" />
  </inertial>
</link>

<joint name="camera_joint" type="fixed">
  <parent link="base_link"/>
  <child link="camera_link"/>
  <origin xyz="0.215 0 0.05" rpy="0 0 0"/>
</joint>

<link name="camera_depth_frame"/>

<joint name="camera_depth_joint" type="fixed">
  <origin xyz="0 0 0" rpy="${-pi/2} 0 ${-pi/2}"/>
  <parent link="camera_link"/>
  <child link="camera_depth_frame"/>
</joint>

</robot>
